Workbook

Sheet DB 수집
A1: NO | D1: 리드 데이터 | J1: 전화 상담 수집 데이터 | P1: 대면 상담 수집 데이터 | AL1: (선택사항)
B2: 진행 단계 | C2: 세일즈 상태 | D2: 리드유형 | E2: 유입경로 (드롭다운) | F2: 수집 날짜 | G2: 이름 | H2: 연락처 (010-0000-0000) | I2: 비고 | J2: 전화 상담일 (yyyy.mm.dd) | K2: 기존 보유차량 매입 여부 (O,X) | L2: 기존차량 | M2: 교체사유 | N2: 차량 구매시기 | O2: 비고 | P2: 대면 상담일 (yyyy.mm.dd) | Q2: 매매 계약일 (yyyy.mm.dd) | R2: 차량 출고일 (yyyy.mm.dd) | S2: 고객 유형 (드롭다운) | T2: 구매 방식 (드롭다운) | U2: 캐피탈 조회 (O,X) | V2: 실행 가능여부 (O,X) | W2: 추천인 | X2: 출생연도 | Y2: 지역 (도,특별시) | Z2: 지역 (시,군,구) | AA2: 차종 | AB2: 차량 대수 | AC2: 특장 | AD2: 상온 / 냉동 | AE2: 옵션(특장) | AF2: 차량 가격 | AG2: 총 가격 (단위 : 만원) | AH2: 선수금 (단위 : 만원) | AI2: 월납액 | AJ2: 개월 수 | AK2: 상담메모 | AL2: 구매목적 | AM2: 중요요소
A3: 예시 | B3: 1.성숙리드 | C3: 종결 | D3: 리드(오프라인) | E3: 개인(슈마허) | F3: 46161 | G3: 최도준 | H3: 010-1111-1234 | I3: 예시 | J3: 46161 | K3: O | L3: X | M3: X | N3: 1개월 이내 | O3: 예시 | P3: 46162 | Q3: 46166 | R3: 46143 | S3: 개인 | T3: 캐피탈 | U3: O | V3: O | W3: 젤로 | X3: 1997 | Y3: 서울특별시 | Z3: 관악구 | AA3: 스테고K | AB3: 1 | AC3: 저상 | AD3: 냉동 | AE3: 도색(형광), 문 3개 | AF3: 50000000 | AG3: =AB3*AF3 -> 50000000 | AH3: 1000 | AI3: 520000 | AJ3: 60
A4: 1 | B4: 3.대면상담 | C4: 종결 | D4: 리드(오프라인) | E4: 개인(슈마허) | F4: 46129 | G4: 양국환 | H4: 010-3228-3996 | I4: 바로 대면상담으로 진행 | J4: 46129 | K4: X | L4: O | M4: 기존 내연 임대차량 처분 | P4: 46129 | S4: 개인 | W4: X | X4: 1962 | Y4: 서울 특별시 | Z4: 영등포 | AA4: 스테고Z(구독) | AB4: 1 | AD4: 냉동 | AE4: 4도어 | AF4: 500000 | AG4: =AB4*AF4 -> 500000 | AH4: 0 | AI4: 500000 | AJ4: 무기한 | AK4: 필리핀으로 일이 있어 7월 필리핀 입국 하여, 취소
A5: 2 | B5: 4.정식계약 | C5: 진행 중 | D5: 리드(오프라인) | E5: 개인(슈마허) | F5: 46161 | G5: 전진영 | H5: 010-6400-1144 | I5: 바로 대면상담으로 진행 | J5: 46161 | K5: O | L5: O | M5: 기존 가스차 처분 | N5: 2개월 이내 | P5: 46184 | Q5: 46184 | R5: 46184 | S5: 개인 | T5: 캐피탈 | U5: X | W5: X | X5: 1983 | Y5: 경기도 | Z5: 안양시 | AA5: 스테고K | AB5: 1 | AC5: 저상 | AD5: 냉동 | AE5: 4도어 | AF5: 0 | AG5: =AB5*AF5 -> 0 | AK5: 정식계약 완료. 캐피탈 승인 5900만원 가능 통보 받음
A6: 3 | B6: 2.전화상담 | C6: 종결 | D6: 리드(오프라인) | E6: 개인(슈마허) | F6: 46166 | G6: 박순식 | H6: 010-8774-7077 | I6: 바로 전화상담으로 진행 | J6: 46166 | K6: X | L6: 모름 | P6: 46185 | S6: 개인 | T6: 캐피탈 | W6: X | Y6: 서울특별시 | Z6: 영둥포 | AG6: =AB6*AF6 -> 0 | AK6: 스테고z 에 붙어있는 광고문 보고 전화 주심. 차량구매,일거리 상세 프로세스 설명 완료. 추후 고민 후 연락 주신다 함.
A7: 4 | B7: 3.대면상담 | C7: 종결 | D7: 리드(오프라인) | E7: 개인(슈마허) | F7: 46164 | G7: 조영술 | H7: 010-4717-6760 | I7: 바로 대면상담으로 진행 | J7: 46164 | K7: X | L7: O | M7: 기존 임대차량 처분 | P7: 46185 | S7: 개인 | U7: X | W7: 이현구 | X7: 1977 | Y7: 군포시 | Z7: 산본 | AA7: 스테고K | AB7: 1 | AC7: 저상 | AD7: 냉동 | AE7: 4도어 | AF7: 0 | AG7: =AB7*AF7 -> 0 | AK7: 월 요금이 부담스러워 , 중고차로 따로 저렴하게 구매 하심. 약 1년 정도 하시다가 pv5 구매 예정.
A8: 5 | B8: 2.전화상담 | C8: 종결 | D8: 리드(오프라인) | E8: 로드쇼 | F8: 46168 | G8: 박수용 | H8: 010-5359-1982 | I8: 생각 더 해보고 미팅 잡겠다고 하심 | AG8: =AB8*AF8 -> 0
A9: 6 | B9: 2.전화상담 | C9: 종결 | D9: 리드(오프라인) | E9: 로드쇼 | F9: 46168 | G9: 박수준 | H9: 010-5690-9198 | I9: 현재 타고있는 차량 처분 후 말씀 나누자고 함 | AG9: =AB9*AF9 -> 0
A10: 7 | B10: 2.전화상담 | C10: 종결 | D10: 리드(오프라인) | E10: 로드쇼 | F10: 46168 | G10: 이규원 | H10: 010-6422-1728 | I10: 자기차 말고 아버지 차량 바꿔드린다고 함. 현재 아버지가 몸 때문에 쉬고 계셔서 복귀쯤 연락 주신다고 함 | AG10: =AB10*AF10 -> 0
A11: 8 | B11: 2.전화상담 | C11: 종결 | D11: 리드(오프라인) | E11: 로드쇼 | F11: 46168 | G11: 김경민 | H11: 010-2203-7041 | I11: 안산다고 전달 받음 | AG11: =AB11*AF11 -> 0
A12: 9 | B12: 2.전화상담 | C12: 종결 | D12: 리드(오프라인) | E12: 로드쇼 | F12: 46168 | G12: 김주창 | H12: 010-4953-4080 | I12: 중고차로 더 알아보고 연락 주신다고 함. | AG12: =AB12*AF12 -> 0
A13: 10 | B13: 2.전화상담 | C13: 종결 | D13: 리드(오프라인) | E13: 로드쇼 | F13: 46168 | G13: 이상근 | H13: 010-5849-5960 | I13: 2회 이상 부재 | AG13: =AB13*AF13 -> 0
A14: 11 | B14: 2.전화상담 | C14: 종결 | D14: 리드(오프라인) | E14: 로드쇼 | F14: 46168 | G14: 임호빈 | H14: 010-5327-8314 | I14: 2회 이상 부재 | AG14: =AB14*AF14 -> 0
A15: 12 | B15: 2.전화상담 | C15: 종결 | D15: 리드(오프라인) | E15: 로드쇼 | F15: 46168 | G15: 문성욱 | H15: 010-2344-9056 | I15: 2회 이상 부재 | AG15: =AB15*AF15 -> 0 | AK15: *7월 넘버 이슈로 인해, 7월 출고 가능하면 4대 구매 가능*
A16: 13 | B16: 2.전화상담 | C16: 종결 | D16: 리드(오프라인) | E16: 로드쇼 | F16: 46168 | G16: 김미자 | H16: 010-3088-1395 | I16: 스테고 수리 문의지 사려고 기입한게 아니라고 전달받음 | AG16: =AB16*AF16 -> 0 | AK16: A/S 스테고-Z 차량 건의사항 문의 (브레이크)
A17: 14 | B17: 2.전화상담 | C17: 종결 | D17: 리드(오프라인) | E17: 로드쇼 | F17: 46168 | G17: 박상희 | H17: 010-3168-0392 | I17: 2회 이상 부재 | AG17: =AB17*AF17 -> 0
A18: 15 | B18: 2.전화상담 | C18: 종결 | D18: 리드(오프라인) | E18: 로드쇼 | F18: 46168 | G18: 김준성 | H18: 010-8113-9313 | I18: 2회 이상 부재 | AG18: =AB18*AF18 -> 0
A19: 16 | B19: 2.전화상담 | C19: 종결 | D19: 리드(오프라인) | E19: 로드쇼 | F19: 46168 | G19: 정해수 | H19: 010-5363-9108 | I19: 2회 이상 부재 | AG19: =AB19*AF19 -> 0
A20: 304 | B20: 2.전화상담 | C20: 종결 | D20: 리드(오프라인) | E20: 로드쇼 | F20: 46178 | G20: 심원흠 | H20: 010-3158-6632 | I20: 새차 산지 3개월 밖에 안돼서 아직 생각 없다고 함. 매입 이야기는 꺼냈으나 고민 해보신다고 함. | AG20: =AB20*AF20 -> 0
A21: 305 | B21: 3.대면상담 | C21: 종결 | D21: 리드(오프라인) | E21: 로드쇼 | F21: 46178 | G21: 범석환 | H21: 010-5620-3342 | I21: 캐피탈 신용 승인거절 ( 아담님 : 투자생각으로 임대 가격올려서 임대로 전향 ) 스테고 > pv5 | J21: 46178 | L21: X | AG21: =AB21*AF21 -> 0 | AK21: 커머셜 승인 거절/ 슈마허 개인 캐피탈사 승인거절 로 인해 불가 예상 ( 아담님 : 투자생각으로 임대 가격올려서 임대로 전향 )
A22: 306 | B22: 2.전화상담 | C22: 종결 | D22: 리드(오프라인) | E22: 로드쇼 | F22: 46178 | G22: 김현진 | H22: 010-4967-7666 | I22: 2회 이상 부재 | AG22: =AB22*AF22 -> 0
A23: 307 | B23: 1.성숙리드 | C23: 진행 중 | D23: 리드(오프라인) | E23: 로드쇼 | F23: 46178 | G23: 조성운 | H23: 010-2922-3874 | I23: 부재 중 | AG23: =AB23*AF23 -> 0
A24: 308 | B24: 1.성숙리드 | C24: 진행 중 | D24: 리드(오프라인) | E24: 로드쇼 | F24: 46178 | G24: 윤정헌 | H24: 010-8909-5858 | I24: 0625 오전 통화 하였으나, 부재. 저녁에 다시 연락 드릴예정 (안내문자발송완료) | AG24: =AB24*AF24 -> 0
A25: 309 | B25: 1.성숙리드 | C25: 진행 중 | D25: 리드(오프라인) | E25: 로드쇼 | F25: 46178 | G25: 김영남 | H25: 010-3932-5778 | I25: 0625 오전 통화 하였으나, 부재. 저녁에 다시 연락 드릴예정 (안내문자발송완료) | AG25: =AB25*AF25 -> 0
A26: 310 | B26: 1.성숙리드 | C26: 진행 중 | D26: 리드(오프라인) | E26: 로드쇼 | F26: 46178 | G26: 이효연 | H26: 010-4025-7271 | I26: 0625 오전 통화 하였으나, 부재. 저녁에 다시 연락 드릴예정 (안내문자발송완료) | AG26: =AB26*AF26 -> 0
A27: 311 | B27: 1.성숙리드 | C27: 진행 중 | D27: 리드(오프라인) | E27: 로드쇼 | F27: 46178 | G27: 유형룡 | H27: 010-8222-8425 | I27: 0625 오전 통화 하였으나, 부재. 저녁에 다시 연락 드릴예정 (안내문자발송완료) | AG27: =AB27*AF27 -> 0
A28: 312 | B28: 1.성숙리드 | C28: 진행 중 | D28: 리드(오프라인) | E28: 로드쇼 | F28: 46178 | G28: 김지훈 | H28: 010-4867-6338 | I28: 0625 오전 통화 하였으나, 부재. 저녁에 다시 연락 드릴예정 (안내문자발송완료) | AG28: =AB28*AF28 -> 0
A29: 313 | B29: 1.성숙리드 | C29: 진행 중 | D29: 리드(오프라인) | E29: 로드쇼 | F29: 46178 | G29: 박경덕 | H29: 010-4560-9858 | I29: 0625 오전 통화 하였으나, 부재. 저녁에 다시 연락 드릴예정 (안내문자발송완료) | AG29: =AB29*AF29 -> 0
A30: 314 | B30: 1.성숙리드 | C30: 진행 중 | D30: 리드(오프라인) | E30: 로드쇼 | F30: 46193 | G30: 박근 | H30: 010-3827-9668 | I30: 0625 오전 통화 하였으나, 부재. 저녁에 다시 연락 드릴예정 (안내문자발송완료) | AG30: =AB30*AF30 -> 0
A31: 315 | B31: 1.성숙리드 | C31: 진행 중 | D31: 리드(오프라인) | E31: 로드쇼 | F31: 46193 | G31: 조성욱 | H31: 010-6423-3175 | I31: 0625 오전 통화 하였으나, 부재. 저녁에 다시 연락 드릴예정 (안내문자발송완료) | AG31: =AB31*AF31 -> 0
A32: 316 | B32: 1.성숙리드 | C32: 진행 중 | D32: 리드(오프라인) | E32: 로드쇼 | F32: 46193 | G32: 조창혁 | H32: 010-4768-6655 | I32: 0625 오전 통화 하였으나, 부재. 저녁에 다시 연락 드릴예정 (안내문자발송완료) | AG32: =AB32*AF32 -> 0
A33: 317 | B33: 1.성숙리드 | C33: 진행 중 | D33: 리드(오프라인) | E33: 로드쇼 | F33: 46193 | G33: 공정호 | H33: 010-8630-6559 | I33: 0625 오전 통화 하였으나, 부재. 저녁에 다시 연락 드릴예정 (안내문자발송완료) | AG33: =AB33*AF33 -> 0
... A36: 320 | B36: 1.성숙리드 | C36: 진행 중 | D36: 리드(오프라인) | E36: 로드쇼 | F36: 46193 | G36: 김훈 | H36: 010-9646-5057 | I36: 0625 오전 통화 하였으나, 부재. 저녁에 다시 연락 드릴예정 (안내문자발송완료) | AG36: =AB36*AF36 -> 0
A37: 321 | B37: 2.전화상담 | C37: 진행 중 | D37: 리드(오프라인) | E37: 로드쇼 | F37: 46193 | G37: 임경신 | H37: 010-8780-1642 | I37: 0625 오전 통화 완료. ( 다른 일정 중이시라서 문자 남겨놔주면 저녁에 전화 해서 이야기나누기로함) | J37: 46198 | AG37: =AB37*AF37 -> 0
A38: 322 | B38: 1.성숙리드 | C38: 진행 중 | D38: 리드(오프라인) | E38: 로드쇼 | F38: 46193 | G38: 박영민 | H38: 010-2077-6880 | I38: 0625 오전 통화 하였으나, 부재. 저녁에 다시 연락 드릴예정 (안내문자발송완료) | AG38: =AB38*AF38 -> 0
A39: 323 | B39: 2.전화상담 | C39: 진행 중 | D39: 리드(오프라인) | E39: 로드쇼 | F39: 46193 | G39: 이동우 | H39: 010-7651-5550 | I39: 번호가 틀림,, 다시 찾아보고 연락 예정 | J39: 46198 | AG39: =AB39*AF39 -> 0
A40: 324 | B40: 1.성숙리드 | C40: 진행 중 | D40: 리드(오프라인) | E40: 로드쇼 | F40: 46193 | G40: 이정 | H40: 010-8683-8727 | I40: 0625 오전 통화 하였으나, 부재. 저녁에 다시 연락 드릴예정 (안내문자발송완료) | AG40: =AB40*AF40 -> 0
A41: 325 | B41: 1.성숙리드 | C41: 진행 중 | D41: 리드(오프라인) | E41: 로드쇼 | F41: 46193 | G41: 임민휘 | H41: 010-8244-7717 | I41: 0625 오전 통화 하였으나, 부재. 저녁에 다시 연락 드릴예정 (안내문자발송완료) | AG41: =AB41*AF41 -> 0
A42: 326 | AG42: =AB42*AF42 -> 0
...

Sheet 성과 관리
E2: 5월 | F2: 6월 | J2: 7월 | O2: 8월 | S2: 9월 | W2: 10월 | AB2: 11월 | AF2: 12월
E3: 5/1 - 5/31 | F3: 6/1 - 6/7 | G3: 6/8 - 6/14 | H3: 6/15 - 6/21 | I3: 6/22 - 6/28 | J3: 6/29 - 7/5 | K3: 7/6 - 7/12 | L3: 7/13 - 7/19 | M3: 7/20 - 7/26 | N3: 7/27 - 8/2 | O3: 8/3 - 8/9 | P3: 8/10 - 8/16 | Q3: 8/17 - 8/23 | R3: 8/24 - 8/30 | S3: 8/31 - 9/6 | T3: 9/7 - 9/13 | U3: 9/14 - 9/20 | V3: 9/21 - 9/27 | W3: 9/28 - 10/4 | X3: 10/5 - 10/11 | Y3: 10/12 - 10/18 | Z3: 10/19 - 10/24 | AA3: 10/25 - 11/1 | AB3: 11/2 - 11/8 | AC3: 11/9 - 11/15 | AD3: 11/16 - 11/22 | AE3: 11/23 - 11/29 | AF3: 11/30 - 12/6 | AG3: 12/7 - 12/13 | AH3: 12/14 - 12/20 | AI3: 12/21 - 12/27 | AJ3: 12/28 - 1/3 | AK3: 8/17 - 8/23
B4: 항목 | C4: 월간목표 | D4: 누적 성과 | E4: 5월 현황 | F4: 2주차 현황 | G4: 3주차 현황 | H4: 4주차 현황 | I4: 5주차 현황 | J4: 6주차 현황 | K4: 7주차 현황 | L4: 8주차 현황 | M4: 9주차 현황 | N4: 10주차 현황 | O4: 11주차 현황 | P4: 12주차 현황 | Q4: 13주차 현황 | R4: 14주차 현황 | S4: 15주차 현황 | T4: 16주차 현황 | U4: 17주차 현황 | V4: 18주차 현황 | W4: 19주차 현황 | X4: 20주차 현황 | Y4: 21주차 현황 | Z4: 22주차 현황 | AA4: 23주차 현황 | AB4: 24주차 현황 | AC4: 25주차 현황 | AD4: 26주차 현황 | AE4: 27주차 현황 | AF4: 28주차 현황 | AG4: 29주차 현황 | AH4: 30주차 현황 | AI4: 31주차 현황 | AJ4: 32주차 현황 | AK4: 33주차 현황 | AL4: 34주차 현황 | AM4: 35주차 현황 | AN4: 36주차 현황 | AO4: 37주차 현황 | AP4: 38주차 현황 | AQ4: 39주차 현황 | AR4: 40주차 현황 | AS4: 41주차 현황 | AT4: 42주차 현황 | AU4: 43주차 현황 | AV4: 44주차 현황 | AW4: 45주차 현황 | AX4: 46주차 현황 | AY4: 47주차 현황 | AZ4: 48주차 현황 | BA4: 49주차 현황 | BB4: 50주차 현황 | BC4: 51주차 현황 | BD4: 52주차 현황
A5: 성과 | B5: 매출 | C5: =C6*C7 -> 1350000000 | D5: =D6*D7 -> 45000000 | E5: =E6*E7 -> 0 | F5: =F6*F7 -> 0 | G5: =G6*G7 -> 45000000 | H5: =H6*H7 -> 0 | I5: =I6*I7 -> 0 | J5: =J6*J7 -> 0 | ... AJ5: =AJ6*AJ7 -> 0
B6: 객단가 | C6: 45000000 | D6: 45000000 | E6: 45000000 | F6: 45000000 | G6: 45000000 | H6: 45000000 | I6: 45000000 | J6: 45000000 | K6: 45000000 | L6: 45000000 | M6: 45000000 | N6: 45000000 | O6: 45000000 | P6: 45000000 | Q6: 45000000 | R6: 45000000 | S6: 45000000 | T6: 45000000 | U6: 45000000 | V6: 45000000 | W6: 45000000 | X6: 45000000 | Y6: 45000000 | Z6: 45000000 | AA6: 45000000 | AB6: 45000000 | AC6: 45000000 | AD6: 45000000 | AE6: 45000000 | AF6: 45000000 | AG6: 45000000 | AH6: 45000000 | AI6: 45000000 | AJ6: 45000000
B7: 구매확정 수 | C7: 30 | D7: =SUM(E7:BD7) -> 1 | E7: =COUNTIFS('DB 수집'!R4:R713,">=2026-5-1",'DB 수집'!R4:R713,"<=2026-5-31") -> 0 | F7: =COUNTIFS('DB 수집'!R4:R713,">=2026-6-1",'DB 수집'!R4:R713,"<=2026-6-7") -> 0 | G7: =COUNTIFS('DB 수집'!R4:R713,">=2026-6-8",'DB 수집'!R4:R713,"<=2026-6-14") -> 1 | H7: =COUNTIFS('DB 수집'!R4:R713,">=2026-6-15",'DB 수집'!R4:R713,"<=2026-6-21") -> 0 | I7: =COUNTIFS('DB 수집'!R4:R713,">=2026-6-22",'DB 수집'!R4:R713,"<=2026-6-28") -> 0 | J7: 0 | K7: 0 | L7: 0 | M7: 0 | N7: 0 | O7: 0 | P7: 0 | Q7: 0 | R7: 0 | S7: 0 | T7: 0 | U7: 0 | V7: 0 | W7: 0 | X7: 0 | Y7: 0 | Z7: 0 | AA7: 0 | AB7: 0 | AC7: 0 | AD7: 0 | AE7: 0 | AF7: 0 | AG7: 0 | AH7: 0 | AI7: 0 | AJ7: 0
B8: 구매확정 전환율 | C8: 0.5 | D8: =IFERROR(D7/D9,0) -> 1 | E8: =IFERROR(E7/E9,0) -> 0 | F8: =IFERROR(F7/F9,0) -> 0 | G8: =IFERROR(G7/G9,0) -> 1 | H8: =IFERROR(H7/H9,0) -> 0 | I8: =IFERROR(I7/I9,0) -> 0 | J8: =IFERROR(J7/J9,0) -> 0 | K8: =IFERROR(K7/K9,0) -> 0 | ... AJ8: =IFERROR(AJ7/AJ9,0) -> 0
B9: 정식계약 수 | C9: =C7/C8 -> 60 | D9: =SUM(E9:BD9) -> 1 | E9: =COUNTIFS('DB 수집'!Q4:Q713,">=2026-5-1",'DB 수집'!Q4:Q713,"<=2026-5-31") -> 0 | F9: =COUNTIFS('DB 수집'!Q4:Q713,">=2026-6-1",'DB 수집'!Q4:Q713,"<=2026-6-7") -> 0 | G9: =COUNTIFS('DB 수집'!Q4:Q713,">=2026-6-8",'DB 수집'!Q4:Q713,"<=2026-6-14") -> 1 | H9: =COUNTIFS('DB 수집'!Q4:Q713,">=2026-6-15",'DB 수집'!Q4:Q713,"<=2026-6-21") -> 0 | I9: =COUNTIFS('DB 수집'!Q4:Q713,">=2026-6-22",'DB 수집'!Q4:Q713,"<=2026-6-28") -> 0 | J9: 0 | K9: 0 | L9: 0 | M9: 0 | N9: 0 | O9: 0 | P9: 0 | Q9: 0 | R9: 0 | S9: 0 | T9: 0 | U9: 0 | V9: 0 | W9: 0 | X9: 0 | Y9: 0 | Z9: 0 | AA9: 0 | AB9: 0 | AC9: 0 | AD9: 0 | AE9: 0 | AF9: 0 | AG9: 0 | AH9: 0 | AI9: 0 | AJ9: 0
B10: 정식계약 전환율 | C10: 0.2 | D10: =IFERROR(D9/D11,0) -> 0.33333333 | E10: =IFERROR(E9/E11,0) -> 0 | F10: =IFERROR(F9/F11,0) -> 0 | G10: =IFERROR(G9/G11,0) -> 0.33333333 | H10: =IFERROR(H9/H11,0) -> 0 | I10: =IFERROR(I9/I11,0) -> 0 | J10: =IFERROR(J9/J11,0) -> 0 | K10: =IFERROR(K9/K11,0) -> 0 | ... AJ10: =IFERROR(AJ9/AJ11,0) -> 0
B11: 대면상담 수 | C11: =C9/C10 -> 300 | D11: =SUM(E11:BD11) -> 3 | E11: =COUNTIFS('DB 수집'!P4:P713,">=2026-5-1",'DB 수집'!P4:P713,"<=2026-5-31") -> 0 | F11: =COUNTIFS('DB 수집'!P4:P713,">=2026-6-1",'DB 수집'!P4:P713,"<=2026-6-7") -> 0 | G11: =COUNTIFS('DB 수집'!P4:P713,">=2026-6-8",'DB 수집'!P4:P713,"<=2026-6-14") -> 3 | H11: =COUNTIFS('DB 수집'!P4:P713,">=2026-6-15",'DB 수집'!P4:P713,"<=2026-6-21") -> 0 | I11: =COUNTIFS('DB 수집'!P4:P713,">=2026-6-22",'DB 수집'!P4:P713,"<=2026-6-28") -> 0 | J11: 0 | K11: 0 | L11: 0 | M11: 0 | N11: 0 | O11: 0 | P11: 0 | Q11: 0 | R11: 0 | S11: 0 | T11: 0 | U11: 0 | V11: 0 | W11: 0 | X11: 0 | Y11: 0 | Z11: 0 | AA11: 0 | AB11: 0 | AC11: 0 | AD11: 0 | AE11: 0 | AF11: 0 | AG11: 0 | AH11: 0 | AI11: 0 | AJ11: 0
B12: 대면상담 연계율 | C12: 0.2 | D12: =IFERROR(D11/D13,0) -> 0.5 | E12: =IFERROR(E11/E13,0) -> 0 | F12: =IFERROR(F11/F13,0) -> 0 | G12: =IFERROR(G11/G13,0) -> 0 | H12: =IFERROR(H11/H13,0) -> 0 | I12: =IFERROR(I11/I13,0) -> 0 | J12: =IFERROR(J11/J13,0) -> 0 | K12: =IFERROR(K11/K13,0) -> 0 | ... AJ12: =IFERROR(AJ11/AJ13,0) -> 0
B13: 전화상담 수 | C13: =C11/C12 -> 1500 | D13: =SUM(E13:BD13) -> 6 | E13: =COUNTIFS('DB 수집'!J4:J713,">=2026-5-1",'DB 수집'!J4:J713,"<=2026-5-31") -> 3 | F13: =COUNTIFS('DB 수집'!J4:J713,">=2026-6-1",'DB 수집'!J4:J713,"<=2026-6-7") -> 1 | G13: =COUNTIFS('DB 수집'!J4:J713,">=2026-6-8",'DB 수집'!J4:J713,"<=2026-6-14") -> 0 | H13: =COUNTIFS('DB 수집'!J4:J713,">=2026-6-15",'DB 수집'!J4:J713,"<=2026-6-21") -> 0 | I13: =COUNTIFS('DB 수집'!J4:J713,">=2026-6-22",'DB 수집'!J4:J713,"<=2026-6-28") -> 2
B14: 전화상담수 연계율 | C14: 0.8 | D14: =IFERROR(D13/(D15+D16),0) -> 0.17647059 | E14: =IFERROR(E13/(E15+E16),0) -> 0.25 | F14: =IFERROR(F13/(F15+F16),0) -> 0.1 | G14: =IFERROR(G13/(G15+G16),0) -> 0 | H14: =IFERROR(H13/(H15+H16),0) -> 0 | I14: =IFERROR(I13/(I15+I16),0) -> 0 | J14: =IFERROR(J13/(J15+J16),0) -> 0 | K14: =IFERROR(K13/(K15+K16),0) -> 0 | ... AJ14: =IFERROR(AJ13/(AJ15+AJ16),0) -> 0
B15: 리드 데이터(온라인) | C15: =C13/C14*0.6666 -> 1249.875 | D15: =SUM(E15:BD15) -> 0 | E15: =COUNTIFS('DB 수집'!D4:D713,"리드(온라인)",'DB 수집'!F4:F713,">=2026-5-25",'DB 수집'!F4:F713,"<=2026-5-31") -> 0 | F15: =COUNTIFS('DB 수집'!D4:D713,"리드(온라인)",'DB 수집'!F4:F713,">=2026-6-1",'DB 수집'!F4:F713,"<=2026-6-7") -> 0 | G15: =COUNTIFS('DB 수집'!D4:D713,"리드(온라인)",'DB 수집'!F4:F713,">=2026-6-8",'DB 수집'!F4:F713,"<=2026-6-14") -> 0 | H15: =COUNTIFS('DB 수집'!D4:D713,"리드(온라인)",'DB 수집'!F4:F713,">=2026-6-15",'DB 수집'!F4:F713,"<=2026-6-21") -> 0 | I15: =COUNTIFS('DB 수집'!D4:D713,"리드(온라인)",'DB 수집'!F4:F713,">=2026-6-22",'DB 수집'!F4:F713,"<=2026-6-28") -> 0 | J15: 0 | K15: 0 | L15: 0 | M15: 0 | N15: 0 | O15: 0 | P15: 0 | Q15: 0 | R15: 0 | S15: 0 | T15: 0 | U15: 0 | V15: 0 | W15: 0 | X15: 0 | Y15: 0 | Z15: 0 | AA15: 0 | AB15: 0 | AC15: 0 | AD15: 0 | AE15: 0 | AF15: 0 | AG15: 0 | AH15: 0 | AI15: 0 | AJ15: 0
B16: 리드 데이터 | C16: =C13/C14*0.3333 -> 624.9375 | D16: =SUM(E16:BD16) -> 34 | E16: =COUNTIFS('DB 수집'!D4:D713,"리드(오프라인)",'DB 수집'!F4:F713,">=2026-5-25",'DB 수집'!F4:F713,"<=2026-5-31") -> 12 | F16: =COUNTIFS('DB 수집'!D4:D713,"리드(오프라인)",'DB 수집'!F4:F713,">=2026-6-1",'DB 수집'!F4:F713,"<=2026-6-7") -> 10 | G16: =COUNTIFS('DB 수집'!D4:D713,"리드(오프라인)",'DB 수집'!F4:F713,">=2026-6-8",'DB 수집'!F4:F713,"<=2026-6-14") -> 0 | H16: =COUNTIFS('DB 수집'!D4:D713,"리드(오프라인)",'DB 수집'!F4:F713,">=2026-6-15",'DB 수집'!F4:F713,"<=2026-6-21") -> 12 | I16: =COUNTIFS('DB 수집'!D4:D713,"리드(오프라인)",'DB 수집'!F4:F713,">=2026-6-22",'DB 수집'!F4:F713,"<=2026-6-28") -> 0 | J16: =COUNTIFS('DB 수집'!D4:D713,"리드(오프라인)",'DB 수집'!F4:F713,">=2026-6-29",'DB 수집'!F4:F713,"<=2026-7-5") -> 0 | K16: 0 | L16: 0 | M16: 0 | N16: 0 | O16: 0 | P16: 0 | Q16: 0 | R16: 0 | S16: 0 | T16: 0 | U16: 0 | V16: 0 | W16: 0 | X16: 0 | Y16: 0 | Z16: 0 | AA16: 0 | AB16: 0 | AC16: 0 | AD16: 0 | AE16: 0 | AF16: 0 | AG16: 0 | AH16: 0 | AI16: 0 | AJ16: 0
B17: 신청서작성 전환율(온라인) | C17: 0.1 | D17: =IFERROR(D15/D18,0) -> 0 | E17: =IFERROR(E15/E18,0) -> 0 | F17: =IFERROR(F15/F18,0) -> 0 | G17: =IFERROR(G15/G18,0) -> 0 | H17: =IFERROR(H15/H18,0) -> 0 | I17: =IFERROR(I15/I18,0) -> 0 | J17: =IFERROR(J15/J18,0) -> 0 | K17: =IFERROR(K15/K18,0) -> 0 | ... AJ17: =IFERROR(AJ15/AJ18,0) -> 0
A18: 설득용 콘텐츠 | B18: 키콘텐츠 조회수 | C18: =C15/C17 -> 12498.75 | E18: 0 | F18: 0 | G18: 0 | H18: 0 | I18: 0 | J18: 0 | K18: 0 | L18: 0 | M18: 0 | N18: 0 | O18: 0 | P18: 0 | Q18: 0 | R18: 0 | S18: 0 | T18: 0 | U18: 0 | V18: 0 | W18: 0 | X18: 0 | Y18: 0 | Z18: 0 | AA18: 0 | AB18: 0 | AC18: 0 | AD18: 0 | AE18: 0 | AF18: 0 | AG18: 0 | AH18: 0 | AI18: 0 | AJ18: 0
B19: 키콘텐츠 연계율 | C19: 0.2 | E19: =IFERROR(E18/E24,0) -> 0 | F19: =IFERROR(F18/F24,0) -> 0 | G19: =IFERROR(G18/G24,0) -> 0 | H19: =IFERROR(H18/H24,0) -> 0 | I19: =IFERROR(I18/I24,0) -> 0 | J19: =IFERROR(J18/J24,0) -> 0 | K19: =IFERROR(K18/K24,0) -> 0 | L19: =IFERROR(L18/L24,0) -> 0 | ... AJ19: =IFERROR(AJ18/AJ24,0) -> 0
B20: 시청지속시간(초) | C20: 240 | E20: 0 | F20: 0 | G20: 0 | H20: 0 | I20: 0 | J20: 0 | K20: 0 | L20: 0 | M20: 0 | N20: 0 | O20: 0
B21: 클릭률 | C21: 0.1 | E21: 0 | F21: 0 | G21: 0 | H21: 0 | I21: 0 | J21: 0 | K21: 0 | L21: 0 | M21: 0 | N21: 0 | O21: 0
B22: 검색 유입 | C22: - | E22: 0 | F22: 0 | G22: 0 | H22: 0 | I22: 0 | J22: 0 | K22: 0 | L22: 0 | M22: 0 | N22: 0 | O22: 0
B23: 페이지 유입 | C23: - | E23: 0 | F23: 0 | G23: 0 | H23: 0 | I23: 0 | J23: 0 | K23: 0 | L23: 0 | M23: 0 | N23: 0 | O23: 0
A24: 공감용 콘텐츠 | B24: 풀링콘텐츠 조회수 | C24: =C18/C19 -> 62493.75 | E24: 0 | F24: 0 | G24: 0 | H24: 0 | I24: 0 | J24: 0 | K24: 0 | L24: 0 | M24: 0 | N24: 0 | O24: 0 | P24: 0 | Q24: 0 | R24: 0 | S24: 0 | T24: 0 | U24: 0 | V24: 0 | W24: 0 | X24: 0 | Y24: 0 | Z24: 0 | AA24: 0 | AB24: 0 | AC24: 0 | AD24: 0 | AE24: 0 | AF24: 0 | AG24: 0 | AH24: 0 | AI24: 0 | AJ24: 0
B25: 월간 구독자 증가수 | C25: 250 | E25: 0 | F25: 0 | G25: 0 | H25: 0 | I25: 0 | J25: 0 | K25: 0 | L25: 0 | M25: 0 | N25: 0 | O25: 0 | P25: 0 | Q25: 0 | R25: 0 | S25: 0 | T25: 0 | U25: 0 | V25: 0 | W25: 0 | X25: 0 | Y25: 0 | Z25: 0 | AA25: 0 | AB25: 0 | AC25: 0 | AD25: 0 | AE25: 0 | AF25: 0 | AG25: 0 | AH25: 0 | AI25: 0 | AJ25: 0
B26: 구독전환율 | C26: 0.005 | E26: 0 | F26: 0 | G26: 0 | H26: 0 | I26: 0 | J26: 0 | K26: 0 | L26: 0 | M26: 0 | N26: 0 | O26: 0 | P26: 0 | Q26: 0 | R26: 0 | S26: 0 | T26: 0 | U26: 0 | V26: 0 | W26: 0 | X26: 0 | Y26: 0 | Z26: 0 | AA26: 0 | AB26: 0 | AC26: 0 | AD26: 0 | AE26: 0 | AF26: 0 | AG26: 0 | AH26: 0 | AI26: 0 | AJ26: 0
B27: Shorts 조회수
B28: 시청지속시간 | C28: 240 | E28: 0 | F28: 0 | G28: 0 | H28: 0 | I28: 0 | J28: 0 | K28: 0 | L28: 0 | M28: 0 | N28: 0 | O28: 0 | P28: 0 | Q28: 0 | R28: 0 | S28: 0 | T28: 0 | U28: 0 | V28: 0 | W28: 0 | X28: 0 | Y28: 0 | Z28: 0 | AA28: 0 | AB28: 0 | AC28: 0 | AD28: 0 | AE28: 0 | AF28: 0 | AG28: 0 | AH28: 0 | AI28: 0 | AJ28: 0
B29: 클릭률 | C29: 0.1 | E29: 0 | F29: 0 | G29: 0 | H29: 0 | I29: 0 | J29: 0 | K29: 0 | L29: 0 | M29: 0 | N29: 0 | O29: 0 | P29: 0 | Q29: 0 | R29: 0 | S29: 0 | T29: 0 | U29: 0 | V29: 0 | W29: 0 | X29: 0 | Y29: 0 | Z29: 0 | AA29: 0 | AB29: 0 | AC29: 0 | AD29: 0 | AE29: 0 | AF29: 0 | AG29: 0 | AH29: 0 | AI29: 0 | AJ29: 0
B30: 탐색 유입 | C30: - | E30: 0 | F30: 0 | G30: 0 | H30: 0 | I30: 0 | J30: 0 | K30: 0 | L30: 0 | M30: 0 | N30: 0 | O30: 0 | P30: 0 | Q30: 0 | R30: 0 | S30: 0 | T30: 0 | U30: 0 | V30: 0 | W30: 0 | X30: 0 | Y30: 0 | Z30: 0 | AA30: 0 | AB30: 0 | AC30: 0 | AD30: 0 | AE30: 0 | AF30: 0 | AG30: 0 | AH30: 0 | AI30: 0 | AJ30: 0
B31: 하루평균 조회수 | C31: =C24/30 -> 2083.125 | E31: 0 | F31: 0 | G31: 0 | H31: 0 | I31: 0 | J31: 0 | K31: 0 | L31: 0 | M31: 0 | N31: 0 | O31: 0 | P31: 0 | Q31: 0 | R31: 0 | S31: 0 | T31: 0 | U31: 0 | V31: 0 | W31: 0 | X31: 0 | Y31: 0 | Z31: 0 | AA31: 0 | AB31: 0 | AC31: 0 | AD31: 0 | AE31: 0 | AF31: 0 | AG31: 0 | AH31: 0 | AI31: 0 | AJ31: 0
B32: 48시간 조회수 | C32: 0 | E32: 0 | F32: 0 | G32: 0 | H32: 0 | I32: 0 | J32: 0 | K32: 0 | L32: 0 | M32: 0 | N32: 0 | O32: 0 | P32: 0 | Q32: 0 | R32: 0 | S32: 0 | T32: 0 | U32: 0 | V32: 0 | W32: 0 | X32: 0 | Y32: 0 | Z32: 0 | AA32: 0 | AB32: 0 | AC32: 0 | AD32: 0 | AE32: 0 | AF32: 0 | AG32: 0 | AH32: 0 | AI32: 0 | AJ32: 0
B33: 콘텐츠당 필요 조회수 | C33: =C24/C34 -> 3124.6875 | E33: 0 | F33: 0 | G33: 0 | H33: 0 | I33: 0 | J33: 0 | K33: 0 | L33: 0 | M33: 0 | N33: 0 | O33: 0 | P33: 0 | Q33: 0 | R33: 0 | S33: 0 | T33: 0 | U33: 0 | V33: 0 | W33: 0 | X33: 0 | Y33: 0 | Z33: 0 | AA33: 0 | AB33: 0 | AC33: 0 | AD33: 0 | AE33: 0 | AF33: 0 | AG33: 0 | AH33: 0 | AI33: 0 | AJ33: 0
B34: 월 평균 업로드 수 | C34: 20 | E34: 0 | F34: 0 | G34: 0 | H34: 0 | I34: 0 | J34: 0 | K34: 0 | L34: 0 | M34: 0 | N34: 0 | O34: 0 | P34: 0 | Q34: 0 | R34: 0 | S34: 0 | T34: 0 | U34: 0 | V34: 0 | W34: 0 | X34: 0 | Y34: 0 | Z34: 0 | AA34: 0 | AB34: 0 | AC34: 0 | AD34: 0 | AE34: 0 | AF34: 0 | AG34: 0 | AH34: 0 | AI34: 0 | AJ34: 0
